<?xml version="1.0" encoding="utf-8"?>
<robot name="atlas">
  <link name="pelvis">
    <inertial>
      <origin xyz="0.0111 0.0 0.027099999999999996" rpy="0.0 0.0 0.0"/>
      <mass value="9.509"/>
      <inertia ixx="0.12439999999999998" ixy="0.0008" ixz="-0.0007000000000000001" iyy="0.0958" iyz="-0.0005" izz="0.1167"/>
    </inertial>
  </link>
  <link name="ltorso">
    <inertial>
      <origin xyz="-0.0113 0.0 0.07468" rpy="0.0 0.0 0.0"/>
      <mass value="2.27"/>
      <inertia ixx="0.00391" ixy="0.0" ixz="-0.00034" iyy="0.003420000000000001" iyz="0.0" izz="0.0017400000000000002"/>
    </inertial>
  </link>
  <link name="l_uglut">
    <inertial>
      <origin xyz="0.00529 -0.00345 0.00313" rpy="0.0 0.0 0.0"/>
      <mass value="1.959"/>
      <inertia ixx="0.00074" ixy="0.0" ixz="-2.9999999999999997e-5" iyy="0.00069" iyz="0.0" izz="0.00041"/>
    </inertial>
  </link>
  <link name="r_uglut">
    <inertial>
      <origin xyz="0.00529 0.00345 0.00313" rpy="0.0 0.0 0.0"/>
      <mass value="1.959"/>
      <inertia ixx="0.00074" ixy="0.0" ixz="-2.9999999999999997e-5" iyy="0.00069" iyz="0.0" izz="0.00041"/>
    </inertial>
  </link>
  <link name="mtorso">
    <inertial>
      <origin xyz="-0.00816 -0.0306 -0.01312" rpy="0.0 0.0 0.0"/>
      <mass value="0.799"/>
      <inertia ixx="0.0004499999999999999" ixy="-3.9999999999999996e-5" ixz="-5.9999999999999995e-5" iyy="0.00043999999999999996" iyz="-5.000000000000002e-5" izz="0.00047999999999999996"/>
    </inertial>
  </link>
  <link name="l_lglut">
    <inertial>
      <origin xyz="0.03121 0.01705 0.01333" rpy="0.0 0.0 0.0"/>
      <mass value="0.898"/>
      <inertia ixx="0.00106" ixy="-0.00013999999999999993" ixz="0.0006" iyy="0.0012700000000000003" iyz="-1.9999999999999998e-5" izz="0.0006899999999999999"/>
    </inertial>
  </link>
  <link name="r_lglut">
    <inertial>
      <origin xyz="0.03121 -0.01705 0.01333" rpy="0.0 0.0 0.0"/>
      <mass value="0.898"/>
      <inertia ixx="0.00106" ixy="0.00013999999999999993" ixz="0.00015" iyy="0.0012700000000000003" iyz="1.9999999999999998e-5" izz="0.0006899999999999999"/>
    </inertial>
  </link>
  <link name="utorso">
    <inertial>
      <origin xyz="-0.00229 -0.31681 -0.06169000000000001" rpy="0.0 0.0 0.0"/>
      <mass value="84.609"/>
      <inertia ixx="1.6553799999999992" ixy="0.04722" ixz="0.0319" iyy="0.5773600000000001" iyz="1.67343" izz="1.6238899999999994"/>
    </inertial>
  </link>
  <link name="l_uleg">
    <inertial>
      <origin xyz="0.21 0.0 0.0" rpy="0.0 0.0 0.0"/>
      <mass value="8.204"/>
      <inertia ixx="0.02" ixy="0.0" ixz="0.0" iyy="0.08999999999999997" iyz="0.0" izz="0.08999999999999997"/>
    </inertial>
  </link>
  <link name="r_uleg">
    <inertial>
      <origin xyz="0.21 0.0 0.0" rpy="0.0 0.0 0.0"/>
      <mass value="8.204"/>
      <inertia ixx="0.02" ixy="0.0" ixz="0.0" iyy="0.08999999999999997" iyz="0.0" izz="0.08999999999999997"/>
    </inertial>
  </link>
  <link name="l_clav">
    <inertial>
      <origin xyz="0.0 0.0 -0.084" rpy="0.0 0.0 0.0"/>
      <mass value="4.466"/>
      <inertia ixx="0.010999999999999996" ixy="0.0" ixz="0.0" iyy="0.009000000000000001" iyz="0.004" izz="0.004"/>
    </inertial>
  </link>
  <link name="head">
    <inertial>
      <origin xyz="-0.05261 -0.02607 3.0e-5" rpy="0.0 0.0 0.0"/>
      <mass value="2.08756"/>
      <inertia ixx="0.0121" ixy="0.0004499999999999999" ixz="0.0" iyy="0.01337" iyz="0.0" izz="0.013340000000000001"/>
    </inertial>
  </link>
  <link name="r_clav">
    <inertial>
      <origin xyz="0.0 0.0 -0.084" rpy="0.0 0.0 0.0"/>
      <mass value="4.466"/>
      <inertia ixx="0.010999999999999996" ixy="0.0" ixz="0.0" iyy="0.009000000000000001" iyz="0.004" izz="0.004"/>
    </inertial>
  </link>
  <link name="l_lleg">
    <inertial>
      <origin xyz="0.187 -0.001 0.0" rpy="0.0 0.0 0.0"/>
      <mass value="4.515"/>
      <inertia ixx="0.01" ixy="-0.00084" ixz="0.0" iyy="0.07699999999999999" iyz="0.0" izz="0.07600000000000001"/>
    </inertial>
  </link>
  <link name="r_lleg">
    <inertial>
      <origin xyz="0.187 -0.001 0.0" rpy="0.0 0.0 0.0"/>
      <mass value="4.515"/>
      <inertia ixx="0.01" ixy="-0.00084" ixz="0.0" iyy="0.07699999999999999" iyz="0.0" izz="0.07600000000000001"/>
    </inertial>
  </link>
  <link name="l_scap">
    <inertial>
      <origin xyz="0.0 0.0 0.0" rpy="0.0 0.0 0.0"/>
      <mass value="3.899"/>
      <inertia ixx="0.00583" ixy="0.0" ixz="0.0" iyy="0.00583" iyz="0.0" izz="0.00319"/>
    </inertial>
  </link>
  <link name="r_scap">
    <inertial>
      <origin xyz="0.0 0.0 0.0" rpy="0.0 0.0 0.0"/>
      <mass value="3.899"/>
      <inertia ixx="0.00583" ixy="0.0" ixz="0.0" iyy="0.00583" iyz="0.0" izz="0.00319"/>
    </inertial>
  </link>
  <link name="l_talus">
    <inertial>
      <origin xyz="0.0 0.0 0.0" rpy="0.0 0.0 0.0"/>
      <mass value="0.125"/>
      <inertia ixx="1.0e-5" ixy="0.0" ixz="0.0" iyy="1.0e-5" iyz="0.0" izz="1.0e-5"/>
    </inertial>
  </link>
  <link name="r_talus">
    <inertial>
      <origin xyz="0.0 0.0 0.0" rpy="0.0 0.0 0.0"/>
      <mass value="0.125"/>
      <inertia ixx="1.0e-5" ixy="0.0" ixz="0.0" iyy="1.0e-5" iyz="0.0" izz="1.0e-5"/>
    </inertial>
  </link>
  <link name="l_uarm">
    <inertial>
      <origin xyz="0.0 0.0 -0.065" rpy="0.0 0.0 0.0"/>
      <mass value="4.386"/>
      <inertia ixx="0.00656" ixy="0.0" ixz="0.0" iyy="0.00656" iyz="0.0" izz="0.00358"/>
    </inertial>
  </link>
  <link name="r_uarm">
    <inertial>
      <origin xyz="0.0 0.0 0.065" rpy="0.0 0.0 0.0"/>
      <mass value="4.386"/>
      <inertia ixx="0.00656" ixy="0.0" ixz="0.0" iyy="0.00656" iyz="0.0" izz="0.00358"/>
    </inertial>
  </link>
  <link name="l_foot">
    <inertial>
      <origin xyz="0.067 0.0 0.027" rpy="0.0 0.0 0.0"/>
      <mass value="2.41"/>
      <inertia ixx="0.008" ixy="0.0" ixz="0.00436" iyy="0.006999999999999999" iyz="0.0" izz="0.002"/>
    </inertial>
  </link>
  <link name="r_foot">
    <inertial>
      <origin xyz="0.067 0.0 0.027" rpy="0.0 0.0 0.0"/>
      <mass value="2.41"/>
      <inertia ixx="0.008" ixy="0.0" ixz="0.00436" iyy="0.006999999999999999" iyz="0.0" izz="0.002"/>
    </inertial>
  </link>
  <link name="l_larm">
    <inertial>
      <origin xyz="0.0 0.0 0.0" rpy="0.0 0.0 0.0"/>
      <mass value="3.248"/>
      <inertia ixx="0.00446" ixy="0.0" ixz="0.0" iyy="0.00446" iyz="0.0" izz="0.00265"/>
    </inertial>
  </link>
  <link name="r_larm">
    <inertial>
      <origin xyz="0.0 0.0 0.0" rpy="0.0 0.0 0.0"/>
      <mass value="3.248"/>
      <inertia ixx="0.00446" ixy="0.0" ixz="0.0" iyy="0.00446" iyz="0.0" izz="0.00265"/>
    </inertial>
  </link>
  <link name="l_ufarm">
    <inertial>
      <origin xyz="-0.00037 0.00015 -0.08296" rpy="0.0 0.0 0.0"/>
      <mass value="2.4798"/>
      <inertia ixx="0.011949999999999999" ixy="3.0e-5" ixz="0.0" iyy="0.012730000000000002" iyz="0.0" izz="0.00286"/>
    </inertial>
  </link>
  <link name="r_ufarm">
    <inertial>
      <origin xyz="-0.00037 -0.00015 0.08296" rpy="0.0 0.0 0.0"/>
      <mass value="2.4798"/>
      <inertia ixx="0.011949999999999999" ixy="-3.0e-5" ixz="0.0" iyy="0.012730000000000002" iyz="0.0" izz="0.00286"/>
    </inertial>
  </link>
  <link name="l_lfarm">
    <inertial>
      <origin xyz="-0.00163 -0.025150000000000002 0.00017" rpy="0.0 0.0 0.0"/>
      <mass value="0.648"/>
      <inertia ixx="0.0008299999999999999" ixy="0.0" ixz="0.0" iyy="0.00043" iyz="0.0" izz="0.0007599999999999999"/>
    </inertial>
  </link>
  <link name="r_lfarm">
    <inertial>
      <origin xyz="-0.00163 -0.025150000000000002 0.00017" rpy="0.0 0.0 0.0"/>
      <mass value="0.648"/>
      <inertia ixx="0.0008299999999999999" ixy="0.0" ixz="0.0" iyy="0.00043" iyz="0.0" izz="0.0007599999999999999"/>
    </inertial>
  </link>
  <link name="l_hand">
    <inertial>
      <origin xyz="2.0e-5 -0.00014 0.08786" rpy="0.0 0.0 0.0"/>
      <mass value="0.6839"/>
      <inertia ixx="0.0005500000000000001" ixy="-1.0e-5" ixz="0.0" iyy="0.0005599999999999997" iyz="0.0" izz="0.00049"/>
    </inertial>
  </link>
  <link name="r_hand">
    <inertial>
      <origin xyz="-2.0e-5 -0.00014 -0.08786" rpy="0.0 0.0 0.0"/>
      <mass value="0.6839"/>
      <inertia ixx="0.0005500000000000001" ixy="1.0e-5" ixz="0.0" iyy="0.0005599999999999997" iyz="0.0" izz="0.00049"/>
    </inertial>
  </link>
  <joint name="back_bkz" type="revolute">
    <parent link="pelvis"/>
    <child link="ltorso"/>
    <origin xyz="-0.0125 0.0 0.0" rpy="0.0 0.0 0.0"/>
    <axis xyz="0.0 0.0 1.0"/>
    <limit lower="-100000.0" upper="100000.0" effort="30.0" velocity="1.0"/>
  </joint>
  <joint name="l_leg_hpz" type="revolute">
    <parent link="pelvis"/>
    <child link="l_uglut"/>
    <origin xyz="0.0 0.089 0.0" rpy="0.0 0.0 0.0"/>
    <axis xyz="0.0 0.0 1.0"/>
    <limit lower="-100000.0" upper="100000.0" effort="30.0" velocity="1.0"/>
  </joint>
  <joint name="r_leg_hpz" type="revolute">
    <parent link="pelvis"/>
    <child link="r_uglut"/>
    <origin xyz="0.0 -0.089 0.0" rpy="0.0 0.0 0.0"/>
    <axis xyz="0.0 0.0 1.0"/>
    <limit lower="-100000.0" upper="100000.0" effort="30.0" velocity="1.0"/>
  </joint>
  <joint name="back_bky" type="revolute">
    <parent link="ltorso"/>
    <child link="mtorso"/>
    <origin xyz="0.0 0.0 0.162" rpy="-1.5707963705062866 0.0 -0.0"/>
    <axis xyz="0.0 0.0 1.0"/>
    <limit lower="-100000.0" upper="100000.0" effort="30.0" velocity="1.0"/>
  </joint>
  <joint name="l_leg_hpx" type="revolute">
    <parent link="l_uglut"/>
    <child link="l_lglut"/>
    <origin xyz="0.0 0.0 0.0" rpy="3.141592653589793 1.570796282091413 3.141592653589793"/>
    <axis xyz="0.0 0.0 1.0"/>
    <limit lower="-100000.0" upper="100000.0" effort="30.0" velocity="1.0"/>
  </joint>
  <joint name="r_leg_hpx" type="revolute">
    <parent link="r_uglut"/>
    <child link="r_lglut"/>
    <origin xyz="0.0 0.0 0.0" rpy="3.141592653589793 1.570796282091413 3.141592653589793"/>
    <axis xyz="0.0 0.0 1.0"/>
    <limit lower="-100000.0" upper="100000.0" effort="30.0" velocity="1.0"/>
  </joint>
  <joint name="back_bkx" type="revolute">
    <parent link="mtorso"/>
    <child link="utorso"/>
    <origin xyz="0.0 -0.05 0.0" rpy="3.141592653589793 1.570796282091413 3.141592653589793"/>
    <axis xyz="0.0 0.0 1.0"/>
    <limit lower="-100000.0" upper="100000.0" effort="30.0" velocity="1.0"/>
  </joint>
  <joint name="l_leg_hpy" type="revolute">
    <parent link="l_lglut"/>
    <child link="l_uleg"/>
    <origin xyz="0.066 0.0225 0.05" rpy="-1.5707963705062866 0.0 -0.0"/>
    <axis xyz="0.0 0.0 1.0"/>
    <limit lower="-100000.0" upper="100000.0" effort="30.0" velocity="1.0"/>
  </joint>
  <joint name="r_leg_hpy" type="revolute">
    <parent link="r_lglut"/>
    <child link="r_uleg"/>
    <origin xyz="0.066 -0.0225 0.05" rpy="-1.5707963705062866 0.0 -0.0"/>
    <axis xyz="0.0 0.0 1.0"/>
    <limit lower="-100000.0" upper="100000.0" effort="30.0" velocity="1.0"/>
  </joint>
  <joint name="l_arm_shz" type="revolute">
    <parent link="utorso"/>
    <child link="l_clav"/>
    <origin xyz="-0.2256 -0.4776 0.1406" rpy="-2.3561944901923457 1.5707962635746238 2.3561944901923457"/>
    <axis xyz="0.0 0.0 1.0"/>
    <limit lower="-100000.0" upper="100000.0" effort="30.0" velocity="1.0"/>
  </joint>
  <joint name="neck_ay" type="revolute">
    <parent link="utorso"/>
    <child link="head"/>
    <origin xyz="0.0 -0.6215 0.2546" rpy="3.141592653589793 -1.570796282091413 3.141592653589793"/>
    <axis xyz="0.0 0.0 1.0"/>
    <limit lower="-100000.0" upper="100000.0" effort="30.0" velocity="1.0"/>
  </joint>
  <joint name="r_arm_shz" type="revolute">
    <parent link="utorso"/>
    <child link="r_clav"/>
    <origin xyz="0.2256 -0.4776 0.1406" rpy="-2.3561944901923457 -1.5707962635746238 -2.3561944901923457"/>
    <axis xyz="0.0 0.0 1.0"/>
    <limit lower="-100000.0" upper="100000.0" effort="30.0" velocity="1.0"/>
  </joint>
  <joint name="l_leg_kny" type="revolute">
    <parent link="l_uleg"/>
    <child link="l_lleg"/>
    <origin xyz="0.374 0.05 0.0" rpy="0.0 0.0 0.0"/>
    <axis xyz="0.0 0.0 1.0"/>
    <limit lower="-100000.0" upper="100000.0" effort="30.0" velocity="1.0"/>
  </joint>
  <joint name="r_leg_kny" type="revolute">
    <parent link="r_uleg"/>
    <child link="r_lleg"/>
    <origin xyz="0.374 0.05 0.0" rpy="0.0 0.0 0.0"/>
    <axis xyz="0.0 0.0 1.0"/>
    <limit lower="-100000.0" upper="100000.0" effort="30.0" velocity="1.0"/>
  </joint>
  <joint name="l_arm_shx" type="revolute">
    <parent link="l_clav"/>
    <child link="l_scap"/>
    <origin xyz="0.0 -0.11 -0.245" rpy="3.141592653589793 -1.570796282091413 3.141592653589793"/>
    <axis xyz="0.0 0.0 1.0"/>
    <limit lower="-100000.0" upper="100000.0" effort="30.0" velocity="1.0"/>
  </joint>
  <joint name="r_arm_shx" type="revolute">
    <parent link="r_clav"/>
    <child link="r_scap"/>
    <origin xyz="0.0 -0.11 -0.245" rpy="3.141592653589793 1.570796282091413 3.141592653589793"/>
    <axis xyz="0.0 0.0 1.0"/>
    <limit lower="-100000.0" upper="100000.0" effort="30.0" velocity="1.0"/>
  </joint>
  <joint name="l_leg_aky" type="revolute">
    <parent link="l_lleg"/>
    <child link="l_talus"/>
    <origin xyz="0.422 0.0 0.0" rpy="0.0 0.0 0.0"/>
    <axis xyz="0.0 0.0 1.0"/>
    <limit lower="-100000.0" upper="100000.0" effort="30.0" velocity="1.0"/>
  </joint>
  <joint name="r_leg_aky" type="revolute">
    <parent link="r_lleg"/>
    <child link="r_talus"/>
    <origin xyz="0.422 0.0 0.0" rpy="0.0 0.0 0.0"/>
    <axis xyz="0.0 0.0 1.0"/>
    <limit lower="-100000.0" upper="100000.0" effort="30.0" velocity="1.0"/>
  </joint>
  <joint name="l_arm_ely" type="revolute">
    <parent link="l_scap"/>
    <child link="l_uarm"/>
    <origin xyz="-0.016 -0.187 0.0" rpy="1.5707963705062866 -0.0 0.0"/>
    <axis xyz="0.0 0.0 1.0"/>
    <limit lower="-100000.0" upper="100000.0" effort="30.0" velocity="1.0"/>
  </joint>
  <joint name="r_arm_ely" type="revolute">
    <parent link="r_scap"/>
    <child link="r_uarm"/>
    <origin xyz="0.016 -0.187 0.0" rpy="-1.5707963705062866 0.0 -0.0"/>
    <axis xyz="0.0 0.0 1.0"/>
    <limit lower="-100000.0" upper="100000.0" effort="30.0" velocity="1.0"/>
  </joint>
  <joint name="l_leg_akx" type="revolute">
    <parent link="l_talus"/>
    <child link="l_foot"/>
    <origin xyz="0.0 0.0 0.0" rpy="1.5707963705062866 -0.0 0.0"/>
    <axis xyz="0.0 0.0 1.0"/>
    <limit lower="-100000.0" upper="100000.0" effort="30.0" velocity="1.0"/>
  </joint>
  <joint name="r_leg_akx" type="revolute">
    <parent link="r_talus"/>
    <child link="r_foot"/>
    <origin xyz="0.0 0.0 0.0" rpy="1.5707963705062866 -0.0 0.0"/>
    <axis xyz="0.0 0.0 1.0"/>
    <limit lower="-100000.0" upper="100000.0" effort="30.0" velocity="1.0"/>
  </joint>
  <joint name="l_arm_elx" type="revolute">
    <parent link="l_uarm"/>
    <child link="l_larm"/>
    <origin xyz="0.0092 0.0 0.119" rpy="-1.5707963705062866 0.0 -0.0"/>
    <axis xyz="0.0 0.0 1.0"/>
    <limit lower="-100000.0" upper="100000.0" effort="30.0" velocity="1.0"/>
  </joint>
  <joint name="r_arm_elx" type="revolute">
    <parent link="r_uarm"/>
    <child link="r_larm"/>
    <origin xyz="-0.0092 0.0 -0.119" rpy="1.5707963705062866 -0.0 0.0"/>
    <axis xyz="0.0 0.0 1.0"/>
    <limit lower="-100000.0" upper="100000.0" effort="30.0" velocity="1.0"/>
  </joint>
  <joint name="l_arm_uwy" type="revolute">
    <parent link="l_larm"/>
    <child link="l_ufarm"/>
    <origin xyz="-0.00921 -0.29955 0.0" rpy="1.5707963705062866 -0.0 0.0"/>
    <axis xyz="0.0 0.0 1.0"/>
    <limit lower="-100000.0" upper="100000.0" effort="30.0" velocity="1.0"/>
  </joint>
  <joint name="r_arm_uwy" type="revolute">
    <parent link="r_larm"/>
    <child link="r_ufarm"/>
    <origin xyz="0.00921 -0.29955 0.0" rpy="-1.5707963705062866 0.0 -0.0"/>
    <axis xyz="0.0 0.0 1.0"/>
    <limit lower="-100000.0" upper="100000.0" effort="30.0" velocity="1.0"/>
  </joint>
  <joint name="l_arm_mwx" type="revolute">
    <parent link="l_ufarm"/>
    <child link="l_lfarm"/>
    <origin xyz="0.0 0.0 0.0" rpy="-1.5707963705062866 0.0 -0.0"/>
    <axis xyz="0.0 0.0 1.0"/>
    <limit lower="-100000.0" upper="100000.0" effort="30.0" velocity="1.0"/>
  </joint>
  <joint name="r_arm_mwx" type="revolute">
    <parent link="r_ufarm"/>
    <child link="r_lfarm"/>
    <origin xyz="0.0 0.0 0.0" rpy="1.5707963705062866 -0.0 0.0"/>
    <axis xyz="0.0 0.0 1.0"/>
    <limit lower="-100000.0" upper="100000.0" effort="30.0" velocity="1.0"/>
  </joint>
  <joint name="l_arm_lwy" type="revolute">
    <parent link="l_lfarm"/>
    <child link="l_hand"/>
    <origin xyz="0.0 0.0 0.0" rpy="1.5707963705062866 -0.0 0.0"/>
    <axis xyz="0.0 0.0 1.0"/>
    <limit lower="-100000.0" upper="100000.0" effort="30.0" velocity="1.0"/>
  </joint>
  <joint name="r_arm_lwy" type="revolute">
    <parent link="r_lfarm"/>
    <child link="r_hand"/>
    <origin xyz="0.0 0.0 0.0" rpy="-1.5707963705062866 0.0 -0.0"/>
    <axis xyz="0.0 0.0 1.0"/>
    <limit lower="-100000.0" upper="100000.0" effort="30.0" velocity="1.0"/>
  </joint>
</robot>